2019-07-03 23:06:18,703 [ERROR]  Exception occurred while handling uri: 'http://localhost:5005/favicon.ico'
Traceback (most recent call last):
  File "/Users/dinmohameddanabek/miniconda3/lib/python3.7/site-packages/sanic/app.py", line 893, in handle_request
    handler, args, kwargs, uri = self.router.get(request)
  File "/Users/dinmohameddanabek/miniconda3/lib/python3.7/site-packages/sanic/router.py", line 407, in get
    return self._get(request.path, request.method, "")
  File "/Users/dinmohameddanabek/miniconda3/lib/python3.7/site-packages/sanic/router.py", line 469, in _get
    raise NotFound("Requested URL {} not found".format(url))
sanic.exceptions.NotFound: Requested URL /favicon.ico not found
2019-07-03 23:36:12,506 [ERROR]  Exception occurred while handling uri: 'http://localhost:5005/model/parse'
Traceback (most recent call last):
  File "/Users/dinmohameddanabek/miniconda3/lib/python3.7/site-packages/sanic/app.py", line 893, in handle_request
    handler, args, kwargs, uri = self.router.get(request)
  File "/Users/dinmohameddanabek/miniconda3/lib/python3.7/site-packages/sanic/router.py", line 407, in get
    return self._get(request.path, request.method, "")
  File "/Users/dinmohameddanabek/miniconda3/lib/python3.7/site-packages/sanic/router.py", line 446, in _get
    raise method_not_supported
sanic.exceptions.MethodNotSupported: Method GET not allowed for URL /model/parse
